<mujoco>
 <worldbody>
  <light diffuse=".5 .5 .5" pos="0 0 1" dir="0 0 -1"/>
  <geom type="plane" size="20 20 0.1" rgba="0 0 0.9 1"/>
  <body name="parahute" >
     <freejoint/>
      <geom name="Parahute_module_center" pos="0 0 5" type="box" size="0.1 0.02 0.001" mass="0.001"/>
      <geom name="Parahute_module_left_one" pos="0 0.03982568852 4.99825" euler="-5 0 0" type="box" size="0.1 0.02 0.001" mass="0.001"/>
      <geom name="Parahute_module_left_two" pos="0 0.07947706556 4.99298" euler="-10 0 0" type="box" size="0.1 0.02 0.001" mass="0.001"/>
      <geom name="Parahute_module_left_three" pos="0 0.11843119668 4.983926" euler="-15 0 0" type="box" size="0.1 0.02 0.001" mass="0.001"/>
      <site name="Control_lines_parachute_left_front" pos="0.1 0.13843119668 4.97874961909" size="0.01" rgba="0 0.9 0 1"/>
      <site name="Control_lines_parachute_left_mid" pos="0 0.13843119668 4.97874961909" size="0.01" rgba="0 0.9 0 1"/>
      <site name="Control_lines_parachute_left_rear" pos="-0.1 0.13843119668 4.97874961909" size="0.01" rgba="0 0.9 0 1"/>
      <geom name="Parahute_module_right_one" pos="0 -0.03982568852 4.99825" euler="5 0 0" type="box" size="0.1 0.02 0.001" mass="0.001"/>
      <geom name="Parahute_module_right_two" pos="0 -0.07947706556 4.99298" euler="10 0 0" type="box" size="0.1 0.02 0.001" mass="0.001"/>
      <geom name="Parahute_module_right_three" pos="0 -0.11843119668 4.983926" euler="15 0 0" type="box" size="0.1 0.02 0.001" mass="0.001"/>	
      <site name="Control_lines_parachute_right_front" pos="0.1 -0.13843119668 4.97874961909" size="0.01" rgba="0 0.9 0 1"/>
      <site name="Control_lines_parachute_right_mid" pos="0 -0.13843119668 4.97874961909" size="0.01" rgba="0 0.9 0 1"/>
      <site name="Control_lines_parachute_right_rear" pos="-0.1 -0.13843119668 4.97874961909" size="0.01" rgba="0 0.9 0 1"/>
      <body name="weight" >
        <joint type="hinge" axis="1 0 0" pos="0 0 4.6"/>
        <geom name="Module_box" type="box" pos="0 0 4.6" size="0.1 0.1 0.1" mass=".0347"/>
        <site name="Face" pos="0.1 0 4.6" size="0.01" rgba="0.9 0 0 1"/>
        <site name="Control_lines_left" pos="0 0.1 4.7" size="0.01" rgba="0 0.9 0 1"/>
        <site name="Control_lines_right" pos="0 -0.1 4.7" size="0.01" rgba="0 0.9 0 1"/>
      </body>
    </body>
 </worldbody>
 
 <tendon>
    <spatial range = "0 0.21">
      <site site="Control_lines_left"/>
      <site site="Control_lines_parachute_left_front"/>
    </spatial>
    <spatial range = "0 0.2">
      <site site="Control_lines_left"/>
      <site site="Control_lines_parachute_left_mid"/>
    </spatial>
    <spatial range = "0 0.21">
      <site site="Control_lines_left"/>
      <site site="Control_lines_parachute_left_rear"/>
    </spatial>
    <spatial range = "0 0.21">
      <site site="Control_lines_right"/>
      <site site="Control_lines_parachute_right_front"/>
    </spatial>
    <spatial range = "0 0.2">
      <site site="Control_lines_right"/>
      <site site="Control_lines_parachute_right_mid"/>
    </spatial>
    <spatial range = "0 0.21">
      <site site="Control_lines_right"/>
      <site site="Control_lines_parachute_right_rear"/>
    </spatial>
  </tendon>
</mujoco>
